Workbook

Sheet Planilha1
A1: problema | B1: suite | C1: M | D1: D | E1: orcamento | F1: degrau | G1: linha | H1: grupo | I1: grupo_nome | J1: trilha | K1: detalhe
A2: MMF1 | B2: MMF | C2: 2 | D2: 2 | E2: 61 | F2: 1 | G2: 1 | H2: 1 | I2: multimodalidade | J2: A — conjuntos de Pareto múltiplos no espaço de decisão | K2: 2 PSs globais simétricos, frente convexa, D=2 visualizável — teste mais simples do niching
A3: MMF4 | B3: MMF | C3: 2 | D3: 2 | E3: 61 | F3: 2 | G3: 1 | H3: 1 | I3: multimodalidade | J3: A — conjuntos de Pareto múltiplos no espaço de decisão | K3: 4 PSs globais (senos/cossenos) para uma única frente côncava — espelho da PoC
A4: MMF11_L | B4: MMF | C4: 2 | D4: 2 | E4: 61 | F4: 3 | G4: 1 | H4: 1 | I4: multimodalidade | J4: A — conjuntos de Pareto múltiplos no espaço de decisão / falso ótimo — um ótimo local atraente | K4: dezenas de PSs locais e globais; local com fitness próximo do global
A5: MMF16_20 | B5: MMF | C5: 3 | D5: 20 | E5: 619 | F5: chefe | G5: 1 | H5: 1 | I5: multimodalidade | J5: A — conjuntos de Pareto múltiplos no espaço de decisão / falso ótimo — um ótimo local atraente | K5: 3 objetivos, 2 PSs globais + 2 locais, D=20 com 17 variáveis inertes
A6: ZDT4 | B6: ZDT | C6: 2 | D6: 10 | E6: 309 | F6: 1 | G6: 2 | H6: 1 | I6: multimodalidade | J6: B — muitos ótimos locais na paisagem | K6: 21^9 frentes locais em grade regular e separável — paralisação por conservadorismo
A7: DTLZ1 | B7: DTLZ | C7: 3 | D7: 7 | E7: 216 | F7: 2 | G7: 2 | H7: 1 | I7: multimodalidade | J7: B — muitos ótimos locais na paisagem | K7: paisagem hiper-ondulada com milhares de falsas frentes; frente plana 3D
A8: DTLZ3 | B8: DTLZ | C8: 3 | D8: 12 | E8: 371 | F8: 3 | G8: 2 | H8: 1 | I8: multimodalidade | J8: B — muitos ótimos locais na paisagem | K8: esfera côncava + ótimos locais massivos — um dos testes mais difíceis
A9: WFG4 | B9: WFG | C9: 2 | D9: 22 | E9: 681 | F9: chefe | G9: 2 | H9: 1 | I9: multimodalidade | J9: B — muitos ótimos locais na paisagem | K9: colinas grandes e absorventes — laboratório superior ao ZDT4
A10: F17 | B10: BBOB | C10: 2 | D10: 10 | E10: 309 | F10: 1 | G10: 3 | H10: 1 | I10: multimodalidade | J10: C — multimodalidade irregular | K10: 2.º objetivo (Schaffer F7) altamente multimodal e assimétrico (COCO)
A11: F37 | B11: BBOB | C11: 2 | D11: 10 | E11: 309 | F11: 2 | G11: 3 | H11: 1 | I11: multimodalidade | J11: C — multimodalidade irregular | K11: Rastrigin com ~10^n ótimos locais (COCO)
A12: F49 | B12: BBOB | C12: 2 | D12: 10 | E12: 309 | F12: 3 | G12: 3 | H12: 1 | I12: multimodalidade | J12: C — multimodalidade irregular / falso ótimo — um ótimo local atraente | K12: Rastrigin × Gallagher: 101 picos com posição e altura aleatórias (COCO)
A13: F55 | B13: BBOB | C13: 2 | D13: 10 | E13: 309 | F13: chefe | G13: 3 | H13: 1 | I13: multimodalidade | J13: C — multimodalidade irregular / falso ótimo — um ótimo local atraente | K13: Gallagher × Gallagher — nenhuma estrutura global (COCO)
A14: F5 | B14: BBOB | C14: 2 | D14: 10 | E14: 309 | F14: 1 | G14: 4 | H14: 2 | I14: não separabilidade | J14: - | K14: só o 2.º objetivo (crista aguda) é não separável (COCO)
A15: F17 | B15: BBOB | C15: 2 | D15: 10 | E15: 309 | F15: 1 | G15: 4 | H15: 2 | I15: não separabilidade | J15: - | K15: só o 2.º objetivo (Schaffer F7) é não separável (COCO)
A16: F22 | B16: BBOB | C16: 2 | D16: 10 | E16: 309 | F16: 2 | G16: 4 | H16: 2 | I16: não separabilidade | J16: - | K16: os dois objetivos não separáveis, ambos unimodais (COCO)
A17: F37 | B17: BBOB | C17: 2 | D17: 10 | E17: 309 | F17: 2 | G17: 4 | H17: 2 | I17: não separabilidade | J17: - | K17: os dois objetivos não separáveis; 2.º multimodal (COCO)
A18: F49 | B18: BBOB | C18: 2 | D18: 10 | E18: 309 | F18: 3 | G18: 4 | H18: 2 | I18: não separabilidade | J18: - | K18: os dois objetivos não separáveis e multimodais (COCO)
A19: F55 | B19: BBOB | C19: 2 | D19: 10 | E19: 309 | F19: 3 | G19: 4 | H19: 2 | I19: não separabilidade | J19: - | K19: os dois objetivos não separáveis e multimodais (COCO)
A20: WFG2 | B20: WFG | C20: 2 | D20: 22 | E20: 681 | F20: 3 | G20: 4 | H20: 2 | I20: não separabilidade | J20: - | K20: variáveis dependentes por construção (redução não separável) + frente desconexa
A21: WFG9 | B21: WFG | C21: 2 | D21: 22 | E21: 681 | F21: chefe | G21: 4 | H21: 2 | I21: não separabilidade | J21: - | K21: não separabilidade total + viés dependente de parâmetro + enganosidade
A22: WFG5 | B22: WFG | C22: 2 | D22: 22 | E22: 681 | F22: 1 | G22: 5 | H22: 3 | I22: geometria da landscape | J22: enganosidade / falsos ótimos | K22: enganosidade pura: bacia do falso ótimo gigantesca, global num alfinete; separável
A23: WFG9 | B23: WFG | C23: 2 | D23: 22 | E23: 681 | F23: chefe | G23: 5 | H23: 3 | I23: geometria da landscape | J23: enganosidade / falsos ótimos | K23: enganosidade + não separabilidade total + viés
A24: WFG1 | B24: WFG | C24: 2 | D24: 22 | E24: 681 | F24: 1 | G24: 6 | H24: 3 | I24: geometria da landscape | J24: regiões planas | K24: regiões planas massivas + viés polinomial — falsa certeza do modelo
A25: DDMOP7 | B25: reais | C25: 2 | D25: 17 | E25: 526 | F25: chefe | G25: 6 | H25: 3 | I25: geometria da landscape | J25: regiões planas | K25: objetivos quantizados (18 valores) + zona morta: platôs onde x muda e F não muda (só HV; asterisco C14)
A26: ZDT6 | B26: ZDT | C26: 2 | D26: 10 | E26: 309 | F26: 1 | G26: 7 | H26: 3 | I26: geometria da landscape | J26: heterocedasticidade / densidade irregular | K26: densidade cai perto da frente — small data onde precisa de precisão
A27: DTLZ4 | B27: DTLZ | C27: 3 | D27: 12 | E27: 371 | F27: 2 | G27: 7 | H27: 3 | I27: geometria da landscape | J27: heterocedasticidade / densidade irregular | K27: evolução do ZDT6 para 3D: viés paramétrico fortíssimo
A28: F22 | B28: BBOB | C28: 2 | D28: 10 | E28: 309 | F28: chefe | G28: 7 | H28: 3 | I28: geometria da landscape | J28: heterocedasticidade / densidade irregular | K28: setor atrativo: só um hipercone de volume ~(1/2)^n tem valores baixos (COCO/cap. 4)
A29: MMF1 | B29: MMF | C29: 2 | D29: 2 | E29: 61 | F29: 0 | G29: 8 | H29: 4 | I29: geometria do front (côncavo, desconexo) | J29: convexa — sanidade | K29: frente convexa amigável; D=2
A30: RE21 | B30: reais | C30: 2 | D30: 4 | E30: 123 | F30: 0 | G30: 8 | H30: 4 | I30: geometria do front (côncavo, desconexo) | J30: convexa — sanidade | K30: cap. 4: frente convexa; problema real simples; D=4
A31: F1 | B31: BBOB | C31: 2 | D31: 10 | E31: 309 | F31: 0 | G31: 8 | H31: 4 | I31: geometria do front (côncavo, desconexo) | J31: convexa — sanidade | K31: COCO: frente convexa, PS em reta — o problema biobjetivo mais simples; D=10
A32: ZDT1 | B32: ZDT | C32: 2 | D32: 30 | E32: 929 | F32: 0 | G32: 8 | H32: 4 | I32: geometria do front (côncavo, desconexo) | J32: convexa — sanidade | K32: convexa, contínua, separável, sem ótimos locais; D=30
A33: MMF4 | B33: MMF | C33: 2 | D33: 2 | E33: 61 | F33: 1 | G33: 8 | H33: 4 | I33: geometria do front (côncavo, desconexo) | J33: côncava | K33: frente côncava — atrai para as pontas
A34: DTLZ2 | B34: DTLZ | C34: 3 | D34: 12 | E34: 371 | F34: 2 | G34: 8 | H34: 4 | I34: geometria do front (côncavo, desconexo) | J34: côncava | K34: esfera côncava 3D sem ótimos locais — controle volumétrico
A35: ZDT6 | B35: ZDT | C35: 2 | D35: 10 | E35: 309 | F35: 3 | G35: 8 | H35: 4 | I35: geometria do front (côncavo, desconexo) | J35: côncava | K35: côncava + densidade irregular (2 objetivos)
A36: DTLZ4 | B36: DTLZ | C36: 3 | D36: 12 | E36: 371 | F36: 3 | G36: 8 | H36: 4 | I36: geometria do front (côncavo, desconexo) | J36: côncava | K36: a mesma esfera côncava do DTLZ2 + densidade irregular (3 objetivos) — par do ZDT6
A37: DTLZ3 | B37: DTLZ | C37: 3 | D37: 12 | E37: 371 | F37: chefe | G37: 8 | H37: 4 | I37: geometria do front (côncavo, desconexo) | J37: côncava | K37: côncava + ótimos locais
A38: ZDT3 | B38: ZDT | C38: 2 | D38: 30 | E38: 929 | F38: 1 | G38: 9 | H38: 4 | I38: geometria do front (côncavo, desconexo) | J38: desconexa | K38: 5 segmentos; separável; unimodal no espaço de decisão — alucinação de pontes
A39: DTLZ7 | B39: DTLZ | C39: 3 | D39: 22 | E39: 681 | F39: 2 | G39: 9 | H39: 4 | I39: geometria do front (côncavo, desconexo) | J39: desconexa | K39: 4 ilhas em 3 objetivos — arquipélago 3D
A40: WFG2 | B40: WFG | C40: 2 | D40: 22 | E40: 681 | F40: chefe | G40: 9 | H40: 4 | I40: geometria do front (côncavo, desconexo) | J40: desconexa | K40: ilhas + variáveis dependentes
...

Sheet Planilha2
A1: problema | C1: outros | D1: geometria
A2: MMF1 | B2: =COUNTIFS(Planilha1!$A$2:$A$40,A2) -> 2 | C2: =COUNTIFS(Planilha1!$A$2:$A$28,A2) -> 1 | D2: =COUNTIFS(Planilha1!$A$29:$A$40,A2) -> 1
A3: MMF4 | B3: =COUNTIFS(Planilha1!$A$2:$A$40,A3) -> 2 | C3: =COUNTIFS(Planilha1!$A$2:$A$28,A3) -> 1 | D3: =COUNTIFS(Planilha1!$A$29:$A$40,A3) -> 1
A4: MMF11_L | B4: =COUNTIFS(Planilha1!$A$2:$A$40,A4) -> 1 | C4: =COUNTIFS(Planilha1!$A$2:$A$28,A4) -> 1 | D4: =COUNTIFS(Planilha1!$A$29:$A$40,A4) -> 0
A5: MMF16_20 | B5: =COUNTIFS(Planilha1!$A$2:$A$40,A5) -> 1 | C5: =COUNTIFS(Planilha1!$A$2:$A$28,A5) -> 1 | D5: =COUNTIFS(Planilha1!$A$29:$A$40,A5) -> 0
A6: ZDT4 | B6: =COUNTIFS(Planilha1!$A$2:$A$40,A6) -> 1 | C6: =COUNTIFS(Planilha1!$A$2:$A$28,A6) -> 1 | D6: =COUNTIFS(Planilha1!$A$29:$A$40,A6) -> 0
A7: DTLZ1 | B7: =COUNTIFS(Planilha1!$A$2:$A$40,A7) -> 1 | C7: =COUNTIFS(Planilha1!$A$2:$A$28,A7) -> 1 | D7: =COUNTIFS(Planilha1!$A$29:$A$40,A7) -> 0
A8: DTLZ3 | B8: =COUNTIFS(Planilha1!$A$2:$A$40,A8) -> 2 | C8: =COUNTIFS(Planilha1!$A$2:$A$28,A8) -> 1 | D8: =COUNTIFS(Planilha1!$A$29:$A$40,A8) -> 1
A9: WFG4 | B9: =COUNTIFS(Planilha1!$A$2:$A$40,A9) -> 1 | C9: =COUNTIFS(Planilha1!$A$2:$A$28,A9) -> 1 | D9: =COUNTIFS(Planilha1!$A$29:$A$40,A9) -> 0
A10: F17 | B10: =COUNTIFS(Planilha1!$A$2:$A$40,A10) -> 2 | C10: =COUNTIFS(Planilha1!$A$2:$A$28,A10) -> 2 | D10: =COUNTIFS(Planilha1!$A$29:$A$40,A10) -> 0
A11: F37 | B11: =COUNTIFS(Planilha1!$A$2:$A$40,A11) -> 2 | C11: =COUNTIFS(Planilha1!$A$2:$A$28,A11) -> 2 | D11: =COUNTIFS(Planilha1!$A$29:$A$40,A11) -> 0
A12: F49 | B12: =COUNTIFS(Planilha1!$A$2:$A$40,A12) -> 2 | C12: =COUNTIFS(Planilha1!$A$2:$A$28,A12) -> 2 | D12: =COUNTIFS(Planilha1!$A$29:$A$40,A12) -> 0
A13: F55 | B13: =COUNTIFS(Planilha1!$A$2:$A$40,A13) -> 2 | C13: =COUNTIFS(Planilha1!$A$2:$A$28,A13) -> 2 | D13: =COUNTIFS(Planilha1!$A$29:$A$40,A13) -> 0
... A29: ESTOQUE40 | B29: =COUNTIFS(Planilha1!$A$2:$A$40,A29) -> 0 | C29: =COUNTIFS(Planilha1!$A$2:$A$28,A29) -> 0 | D29: =COUNTIFS(Planilha1!$A$29:$A$40,A29) -> 0
